Workbook

Sheet Resumen Ejecutivo
A1: Resumen Ejecutivo — Cambio Tecnología Sunmi | La Pampa | J1: 📊 Avance Total del Proyecto
J2: ='Resumen Ejecutivo'!G11 -> 0.59187069
A3: Proyecto: | B3: Cambio Tecnología Sunmi — La Pampa | P3: 20% | T3: 40% | X3: 60% | AB3: 80% | AF3: 100%
A4: Fecha Inicio: | B4: 46244
A5: Fecha Fin Estimada: | B5: 46290
A7: Sección | B7: Agencias | C7: Back | D7: Sunmi | E7: LH | F7: Tjs | G7: % Avance | H7: Estado General
A8: Capital | B8: 28 | C8: ='Gantt Capital'!C35 -> 25 | D8: ='Gantt Capital'!D35 -> 161 | E8: ='Gantt Capital'!E35 -> 29 | F8: ='Gantt Capital'!F35 -> 132 | G8: ='Gantt Capital'!J35 -> 0.77586207 | H8: =IF(G8=1,"Completado",IF(G8>=0.5,"En Avance",IF(G8>0,"En Proceso","Pendiente"))) -> En Avance
A9: Interior | B9: 72 | C9: ='Gantt Interior'!D79 -> 47 | D9: ='Gantt Interior'!E79 -> 344 | E9: ='Gantt Interior'!F79 -> 74 | F9: ='Gantt Interior'!G79 -> 270 | G9: ='Gantt Interior'!K79 -> 0.34583333 | H9: =IF(G9=1,"Completado",IF(G9>=0.5,"En Avance",IF(G9>0,"En Proceso","Pendiente"))) -> En Proceso
A10: Puesta en Marcha (Logística) | G10: ='Gantt Logística'!K17 -> 0.7175 | H10: =IF(G10=1,"Completado",IF(G10>=0.5,"En Avance",IF(G10>0,"En Proceso","Pendiente"))) -> En Avance
A11: TOTAL GENERAL | B11: 100 | C11: ='Gantt Capital'!C35 + 'Gantt Interior'!D79 -> 72 | D11: ='Gantt Capital'!D35 + 'Gantt Interior'!E79 -> 505 | E11: ='Gantt Capital'!E35 + 'Gantt Interior'!F79 -> 103 | F11: ='Gantt Capital'!F35 + 'Gantt Interior'!G79 -> 402 | G11: =(('Gantt Capital'!J35*B8+'Gantt Interior'!K79*B9)/(B8+B9) + G10)/2 -> 0.59187069 | H11: =IF(G11=1,"Completado",IF(G11>=0.5,"En Avance",IF(G11>0,"En Proceso","Pendiente"))) -> En Avance

Sheet Gantt Logística
A1: Cambio Tecnología Sunmi — La Pampa | Logística Equipos/Contrato | O1: 📊 Avance General — Logística
A2: Fecha Inicio: | B2: 46174 | C2: Fecha Fin: | D2: 46270 | N2: =AVERAGE(K5:K16) -> 0.7175 | O2: =AVERAGE(K5:K16) -> 0.7175
U3: 20% | Y3: 40% | AC3: 60% | AG3: 80% | AK3: 100%
A4: N° | B4: Tarea | C4: Nota | G4: recibidas | H4: Inicio | I4: Final | J4: Días | K4: % Avance | L4: Estado | M4: Est.
A5: 1.1 | B5: Recepcion sunmi | G5: 587 | H5: 46167 | I5: =IF(AND(H5<>"",J5<>""),H5+J5,"") -> 46170 | J5: 3 | K5: 1 | L5: =IF(K5=1,"Completado",IF(K5=0.5,"Falta",IF(K5=0,"Pendiente","En Proceso"))) -> Completado | M5: =IF(K5=1,"OK",IF(K5=0,"Pendiente","En Proceso")) -> OK
A6: 1.2 | B6: Ciclado carga | G6: 587 | H6: 46175 | I6: =IF(AND(H6<>"",J6<>""),H6+J6,"") -> 46200 | J6: 25 | K6: 1 | L6: =IF(K6=1,"Completado",IF(K6=0.5,"Falta",IF(K6=0,"Pendiente","En Proceso"))) -> Completado | M6: =IF(K6=1,"OK",IF(K6=0,"Pendiente","En Proceso")) -> OK
B7: carga sistema operativo | G7: 255 | H7: 46220 | I7: =IF(AND(H7<>"",J7<>""),H7+J7,"") -> 46270 | J7: 50 | K7: 0.44
A8: 1.3 | B8: Recepcion e-sim Claro | G8: 567 | H8: 46162 | I8: =IF(AND(H8<>"",J8<>""),H8+J8,"") -> 46178 | J8: 16 | K8: 1 | L8: =IF(K8=1,"Completado",IF(K8=0.5,"Falta",IF(K8=0,"Pendiente","En Proceso"))) -> Completado | M8: =IF(K8=1,"OK",IF(K8=0,"Pendiente","En Proceso")) -> OK
A9: 1.3 | B9: Recepcion sim Personal | G9: 587 | H9: 46189 | I9: =IF(AND(H9<>"",J9<>""),H9+J9,"") -> 46199 | J9: 10 | K9: 1 | L9: =IF(K9=1,"Completado",IF(K9=0.5,"Falta",IF(K9=0,"Pendiente","En Proceso"))) -> Completado | M9: =IF(K9=1,"OK",IF(K9=0,"Pendiente","En Proceso")) -> OK
A10: 1.3 | B10: Recepcion sim Movistar ( Fabrica) | G10: 200 | H10: 46192 | I10: =IF(AND(H10<>"",J10<>""),H10+J10,"") -> 46199 | J10: 7 | K10: 1 | L10: =IF(K10=1,"Completado",IF(K10=0.5,"Falta",IF(K10=0,"Pendiente","En Proceso"))) -> Completado | M10: =IF(K10=1,"OK",IF(K10=0,"Pendiente","En Proceso")) -> OK
A11: 1.3 | B11: Envio tjs/ha Brc. | G11: aproximadamente | H11: 46174 | I11: =IF(AND(H11<>"",J11<>""),H11+J11,"") -> 46269 | J11: 95 | K11: 0 | L11: =IF(K11=1,"Completado",IF(K11=0.5,"Falta",IF(K11=0,"Pendiente","En Proceso"))) -> Pendiente | M11: =IF(K11=1,"OK",IF(K11=0,"Pendiente","En Proceso")) -> Pendiente
A12: 1.3 | B12: Entrega instructivos / video | H12: 45940 | I12: =IF(AND(H12<>"",J12<>""),H12+J12,"") -> 45945 | J12: 5 | K12: 1 | L12: =IF(K12=1,"Completado",IF(K12=0.5,"Falta",IF(K12=0,"Pendiente","En Proceso"))) -> Completado | M12: =IF(K12=1,"OK",IF(K12=0,"Pendiente","En Proceso")) -> OK
A13: 1.5 | B13: Armado cronograma Capital /interior | H13: 46241 | I13: =IF(AND(H13<>"",J13<>""),H13+J13,"") -> 46247 | J13: 6 | K13: 1 | L13: =IF(K13=1,"Completado",IF(K13=0.5,"Falta",IF(K13=0,"Pendiente","En Proceso"))) -> Completado | M13: =IF(K13=1,"OK",IF(K13=0,"Pendiente","En Proceso")) -> OK
A14: 1.6 | B14: Primer reunion avance instalacion con cliente | H14: 46241 | I14: =IF(AND(H14<>"",J14<>""),H14+J14,"") -> 46242 | J14: 1 | K14: 1 | L14: =IF(K14=1,"Completado",IF(K14=0.5,"Falta",IF(K14=0,"Pendiente","En Proceso"))) -> Completado | M14: =IF(K14=1,"OK",IF(K14=0,"Pendiente","En Proceso")) -> OK
A15: 1.7 | B15: Instalacion Capital | H15: 46244 | I15: =IF(AND(H15<>"",J15<>""),H15+J15,"") -> 46254 | J15: 10 | K15: 0.17 | L15: =IF(K15=1,"Completado",IF(K15=0.5,"Falta",IF(K15=0,"Pendiente","En Proceso"))) -> En Proceso | M15: =IF(K15=1,"OK",IF(K15=0,"Pendiente","En Proceso")) -> En Proceso
A16: 1.8 | B16: Instalacion interior | H16: 46258 | I16: =IF(AND(H16<>"",J16<>""),H16+J16,"") -> 46323 | J16: 65 | K16: 0 | L16: =IF(K16=1,"Completado",IF(K16=0.5,"Falta",IF(K16=0,"Pendiente","En Proceso"))) -> Pendiente | M16: =IF(K16=1,"OK",IF(K16=0,"Pendiente","En Proceso")) -> Pendiente
A17: TOTALES | K17: =AVERAGE(K5:K16) -> 0.7175

Sheet Gantt Capital
A1: Cambio Tecnología Sunmi — La Pampa | Capital | N1: 📊 Avance General — Capital
A2: Fecha Inicio: | B2: 46244 | C2: Fecha Fin: | D2: 46256 | M2: =AVERAGE(J5:J33) -> 0.77586207 | N2: =AVERAGE(J5:J32) -> 0.80357143
T3: 20% | X3: 40% | AB3: 60% | AF3: 80% | AJ3: 100%
A4: N° | B4: Agencia | C4: Back | D4: Sunmi | E4: LH | F4: Tjs | G4: Inicio | H4: Final | I4: Días | J4: % Avance | K4: Estado | L4: Est. Capital
A5: 2.1.1 | B5: 1 | D5: =(F5+E5) -> 2 | E5: 1 | F5: 1 | G5: 46253 | H5: =IF(AND(G5<>"",I5<>""),G5+I5,"") -> 46254 | I5: 1 | J5: 0.9 | K5: =IF(J5=1,"Completado",IF(J5=0.9,"Falta LH",IF(J5=0,"Pendiente","En Proceso"))) -> Falta LH | L5: =IF(J5=1,"Operativa",IF(J5=0,"Pendiente","En Proceso")) -> En Proceso
A6: 2.1.2 | B6: 3 | D6: =(F6+E6) -> 3 | E6: 1 | F6: 2 | G6: 46255 | H6: 46255 | I6: 1 | J6: 0.9 | K6: =IF(J6=1,"Completado",IF(J6=0.9,"Falta LH",IF(J6=0,"Pendiente","En Proceso"))) -> Falta LH | L6: =IF(J6=1,"Operativa",IF(J6=0,"Pendiente","En Proceso")) -> En Proceso
A7: 2.1.3 | B7: 4 | D7: =(F7+E7) -> 12 | E7: 1 | F7: 11 | G7: 46253 | H7: =IF(AND(G7<>"",I7<>""),G7+I7,"") -> 46255 | I7: 2 | J7: 0.9 | K7: =IF(J7=1,"Completado",IF(J7=0.9,"Falta LH",IF(J7=0,"Pendiente","En Proceso"))) -> Falta LH | L7: =IF(J7=1,"Operativa",IF(J7=0,"Pendiente","En Proceso")) -> En Proceso
A8: 2.1.4 | B8: 5 | D8: =(F8+E8) -> 16 | E8: 1 | F8: 15 | G8: 46254 | H8: =IF(AND(G8<>"",I8<>""),G8+I8,"") -> 46257 | I8: 3 | J8: 0.9 | K8: =IF(J8=1,"Completado",IF(J8=0.9,"Falta LH",IF(J8=0,"Pendiente","En Proceso"))) -> Falta LH | L8: =IF(J8=1,"Operativa",IF(J8=0,"Pendiente","En Proceso")) -> En Proceso
A9: 2.1.5 | B9: 7 | D9: =(F9+E9) -> 9 | E9: 1 | F9: 8 | G9: 46254 | H9: =IF(AND(G9<>"",I9<>""),G9+I9,"") -> 46255 | I9: 1 | J9: 0.9 | K9: =IF(J9=1,"Completado",IF(J9=0.9,"Falta LH",IF(J9=0,"Pendiente","En Proceso"))) -> Falta LH | L9: =IF(J9=1,"Operativa",IF(J9=0,"Pendiente","En Proceso")) -> En Proceso
A10: 2.1.6 | B10: 9 | D10: =(F10+E10) -> 10 | E10: 1 | F10: 9 | G10: 46253 | H10: =IF(AND(G10<>"",I10<>""),G10+I10,"") -> 46254 | I10: 1 | J10: 0.9 | K10: =IF(J10=1,"Completado",IF(J10=0.9,"Falta LH",IF(J10=0,"Pendiente","En Proceso"))) -> Falta LH | L10: =IF(J10=1,"Operativa",IF(J10=0,"Pendiente","En Proceso")) -> En Proceso
A11: 2.1.7 | B11: 12 | D11: =(F11+E11) -> 8 | E11: 1 | F11: 7 | G11: 46254 | H11: =IF(AND(G11<>"",I11<>""),G11+I11,"") -> 46255 | I11: 1 | J11: 0.9 | K11: =IF(J11=1,"Completado",IF(J11=0.9,"Falta LH",IF(J11=0,"Pendiente","En Proceso"))) -> Falta LH | L11: =IF(J11=1,"Operativa",IF(J11=0,"Pendiente","En Proceso")) -> En Proceso
A12: 2.1.8 | B12: 13 | D12: =(F12+E12) -> 5 | E12: 1 | F12: 4 | G12: 46253 | H12: =IF(AND(G12<>"",I12<>""),G12+I12,"") -> 46254 | I12: 1 | J12: 0.9 | K12: =IF(J12=1,"Completado",IF(J12=0.9,"Falta LH",IF(J12=0,"Pendiente","En Proceso"))) -> Falta LH | L12: =IF(J12=1,"Operativa",IF(J12=0,"Pendiente","En Proceso")) -> En Proceso
A13: 2.1.9 | B13: 14 | D13: =(F13+E13) -> 6 | E13: 1 | F13: 5 | G13: 46244 | H13: =IF(AND(G13<>"",I13<>""),G13+I13,"") -> 46245 | I13: 1 | J13: 0.9 | K13: =IF(J13=1,"Completado",IF(J13=0.9,"Falta LH",IF(J13=0,"Pendiente","En Proceso"))) -> Falta LH | L13: =IF(J13=1,"Operativa",IF(J13=0,"Pendiente","En Proceso")) -> En Proceso
A14: 2.1.10 | B14: 15 | D14: =(F14+E14) -> 6 | E14: 1 | F14: 5 | G14: 46253 | H14: =IF(AND(G14<>"",I14<>""),G14+I14,"") -> 46255 | I14: 2 | J14: 0.9 | K14: =IF(J14=1,"Completado",IF(J14=0.9,"Falta LH",IF(J14=0,"Pendiente","En Proceso"))) -> Falta LH | L14: =IF(J14=1,"Operativa",IF(J14=0,"Pendiente","En Proceso")) -> En Proceso
A15: 2.1.11 | B15: 16 | D15: =(F15+E15) -> 4 | E15: 1 | F15: 3 | G15: 46255 | H15: 46255 | I15: 1 | J15: 0.9 | K15: =IF(J15=1,"Completado",IF(J15=0.9,"Falta LH",IF(J15=0,"Pendiente","En Proceso"))) -> Falta LH | L15: =IF(J15=1,"Operativa",IF(J15=0,"Pendiente","En Proceso")) -> En Proceso
A16: 2.1.12 | B16: 18 | D16: =(F16+E16) -> 4 | E16: 1 | F16: 3 | G16: 46254 | H16: =IF(AND(G16<>"",I16<>""),G16+I16,"") -> 46255 | I16: 1 | J16: 0.9 | K16: =IF(J16=1,"Completado",IF(J16=0.9,"Falta LH",IF(J16=0,"Pendiente","En Proceso"))) -> Falta LH | L16: =IF(J16=1,"Operativa",IF(J16=0,"Pendiente","En Proceso")) -> En Proceso
A17: 2.1.13 | B17: 19 | D17: =(F17+E17) -> 3 | E17: 1 | F17: 2 | G17: 46255 | H17: 46255 | I17: 1 | J17: 1 | K17: =IF(J17=1,"Completado",IF(J17=0.9,"Falta LH",IF(J17=0,"Pendiente","En Proceso"))) -> Completado | L17: =IF(J17=1,"Operativa",IF(J17=0,"Pendiente","En Proceso")) -> Operativa
A18: 2.1.14 | B18: 21 | D18: =(F18+E18) -> 9 | E18: 1 | F18: 8 | G18: 46254 | H18: =IF(AND(G18<>"",I18<>""),G18+I18,"") -> 46256 | I18: 2 | J18: 0.9 | K18: =IF(J18=1,"Completado",IF(J18=0.9,"Falta LH",IF(J18=0,"Pendiente","En Proceso"))) -> Falta LH | L18: =IF(J18=1,"Operativa",IF(J18=0,"Pendiente","En Proceso")) -> En Proceso
A19: 2.1.15 | B19: 24 | D19: =(F19+E19) -> 4 | E19: 1 | F19: 3 | G19: 46254 | H19: =IF(AND(G19<>"",I19<>""),G19+I19,"") -> 46255 | I19: 1 | J19: 0.5 | K19: =IF(J19=1,"Completado",IF(J19=0.9,"Falta LH",IF(J19=0,"Pendiente","En Proceso"))) -> En Proceso | L19: =IF(J19=1,"Operativa",IF(J19=0,"Pendiente","En Proceso")) -> En Proceso
A20: 2.1.16 | B20: 25 | C20: 25 | D20: =(F20+E20) -> 5 | E20: 1 | F20: 4 | G20: 46253 | H20: =IF(AND(G20<>"",I20<>""),G20+I20,"") -> 46254 | I20: 1 | J20: 0.5 | K20: =IF(J20=1,"Completado",IF(J20=0.9,"Falta LH",IF(J20=0,"Pendiente","En Proceso"))) -> En Proceso | L20: =IF(J20=1,"Operativa",IF(J20=0,"Pendiente","En Proceso")) -> En Proceso
A21: 2.1.17 | B21: 26 | D21: =(F21+E21) -> 10 | E21: 1 | F21: 9 | G21: 46255 | H21: 46255 | I21: 2 | J21: 0.9 | K21: =IF(J21=1,"Completado",IF(J21=0.9,"Falta LH",IF(J21=0,"Pendiente","En Proceso"))) -> Falta LH | L21: =IF(J21=1,"Operativa",IF(J21=0,"Pendiente","En Proceso")) -> En Proceso
A22: 2.1.18 | B22: 27 | D22: =(F22+E22) -> 4 | E22: 1 | F22: 3 | G22: 46254 | H22: =IF(AND(G22<>"",I22<>""),G22+I22,"") -> 46255 | I22: 1 | J22: 0.9 | K22: =IF(J22=1,"Completado",IF(J22=0.9,"Falta LH",IF(J22=0,"Pendiente","En Proceso"))) -> Falta LH | L22: =IF(J22=1,"Operativa",IF(J22=0,"Pendiente","En Proceso")) -> En Proceso
A23: 2.1.19 | B23: 28 | D23: =(F23+E23) -> 6 | E23: 1 | F23: 5 | G23: 46253 | H23: =IF(AND(G23<>"",I23<>""),G23+I23,"") -> 46254 | I23: 1 | J23: 0.5 | K23: =IF(J23=1,"Completado",IF(J23=0.9,"Falta LH",IF(J23=0,"Pendiente","En Proceso"))) -> En Proceso | L23: =IF(J23=1,"Operativa",IF(J23=0,"Pendiente","En Proceso")) -> En Proceso
A24: 2.1.20 | B24: 29 | D24: =(F24+E24) -> 3 | E24: 1 | F24: 2 | G24: 46255 | H24: 46255 | I24: 1 | J24: 0.5 | K24: =IF(J24=1,"Completado",IF(J24=0.9,"Falta LH",IF(J24=0,"Pendiente","En Proceso"))) -> En Proceso | L24: =IF(J24=1,"Operativa",IF(J24=0,"Pendiente","En Proceso")) -> En Proceso
A25: 2.1.21 | B25: 30 | D25: =(F25+E25) -> 2 | E25: 1 | F25: 1 | G25: 46255 | H25: 46255 | I25: 1 | J25: 0.9 | K25: =IF(J25=1,"Completado",IF(J25=0.9,"Falta LH",IF(J25=0,"Pendiente","En Proceso"))) -> Falta LH | L25: =IF(J25=1,"Operativa",IF(J25=0,"Pendiente","En Proceso")) -> En Proceso
A26: 2.1.22 | B26: 91 | D26: =(F26+E26) -> 5 | E26: 1 | F26: 4 | G26: 46244 | H26: =IF(AND(G26<>"",I26<>""),G26+I26,"") -> 46245 | I26: 1 | J26: 0.9 | K26: =IF(J26=1,"Completado",IF(J26=0.9,"Falta LH",IF(J26=0,"Pendiente","En Proceso"))) -> Falta LH | L26: =IF(J26=1,"Operativa",IF(J26=0,"Pendiente","En Proceso")) -> En Proceso
A27: 2.1.23 | B27: 95 | D27: =(F27+E27) -> 2 | E27: 1 | F27: 1 | G27: 46255 | H27: =IF(AND(G27<>"",I27<>""),G27+I27,"") -> 46256 | I27: 1 | J27: 1 | K27: =IF(J27=1,"Completado",IF(J27=0.9,"Falta LH",IF(J27=0,"Pendiente","En Proceso"))) -> Completado | L27: =IF(J27=1,"Operativa",IF(J27=0,"Pendiente","En Proceso")) -> Operativa
A28: 2.1.24 | B28: 103 | D28: =(F28+E28) -> 6 | E28: 1 | F28: 5 | G28: 46255 | H28: 46255 | I28: 2 | J28: 0.5 | K28: =IF(J28=1,"Completado",IF(J28=0.9,"Falta LH",IF(J28=0,"Pendiente","En Proceso"))) -> En Proceso | L28: =IF(J28=1,"Operativa",IF(J28=0,"Pendiente","En Proceso")) -> En Proceso
A29: 2.1.25 | B29: 105 | D29: =(F29+E29) -> 4 | E29: 1 | F29: 3 | G29: 46246 | H29: =IF(AND(G29<>"",I29<>""),G29+I29,"") -> 46247 | I29: 1 | J29: 0.9 | K29: =IF(J29=1,"Completado",IF(J29=0.9,"Falta LH",IF(J29=0,"Pendiente","En Proceso"))) -> Falta LH | L29: =IF(J29=1,"Operativa",IF(J29=0,"Pendiente","En Proceso")) -> En Proceso
A30: 2.1.26 | B30: 110 | D30: =(F30+E30) -> 2 | E30: 1 | F30: 1 | G30: 46255 | H30: =IF(AND(G30<>"",I30<>""),G30+I30,"") -> 46256 | I30: 1 | J30: 0.5 | K30: =IF(J30=1,"Completado",IF(J30=0.9,"Falta LH",IF(J30=0,"Pendiente","En Proceso"))) -> En Proceso | L30: =IF(J30=1,"Operativa",IF(J30=0,"Pendiente","En Proceso")) -> En Proceso
A31: 2.1.27 | B31: 135 | D31: =(F31+E31) -> 2 | E31: 1 | F31: 1 | G31: 46255 | H31: 46255 | I31: 1 | J31: 1 | K31: =IF(J31=1,"Completado",IF(J31=0.9,"Falta LH",IF(J31=0,"Pendiente","En Proceso"))) -> Completado | L31: =IF(J31=1,"Operativa",IF(J31=0,"Pendiente","En Proceso")) -> Operativa
A32: 2.1.28 | B32: 136 | D32: =(F32+E32) -> 6 | E32: 1 | F32: 5 | G32: 46254 | H32: =IF(AND(G32<>"",I32<>""),G32+I32,"") -> 46255 | I32: 1 | J32: 0.3 | K32: =IF(J32=1,"Completado",IF(J32=0.9,"Falta LH",IF(J32=0,"Pendiente","En Proceso"))) -> En Proceso | L32: =IF(J32=1,"Operativa",IF(J32=0,"Pendiente","En Proceso")) -> En Proceso
A33: 2.1.29 | B33: 137 | D33: =(F33+E33) -> 3 | E33: 1 | F33: 2 | G33: 46255 | H33: =IF(AND(G33<>"",I33<>""),G33+I33,"") -> 46256 | I33: 1 | J33: 0 | K33: =IF(J33=1,"Completado",IF(J33=0.9,"Falta LH",IF(J33=0,"Pendiente","En Proceso"))) -> Pendiente | L33: =IF(J33=1,"Operativa",IF(J33=0,"Pendiente","En Proceso")) -> Pendiente | M33: Loteria pidio no cambiar las terminales ya que es una proxima baja
A35: TOTALES | C35: =SUM(C5:C33) -> 25 | D35: =SUM(D5:D33) -> 161 | E35: =SUM(E5:E33) -> 29 | F35: =SUM(F5:F33) -> 132 | J35: =AVERAGE(J5:J33) -> 0.77586207

Sheet Gantt Interior
A1: Cambio Tecnología Sunmi — La Pampa | Interior | O1: 📊 Avance General — Interior
A2: Fecha Inicio: | B2: 46209 | D2: Fecha Fin: | E2: 46272 | O2: =AVERAGE(K5:K77) -> 0.34583333
U3: 20% | Y3: 40% | AC3: 60% | AG3: 80% | AK3: 100%
A4: N° | B4: Agencia N° | C4: Localidad | D4: Back | E4: Sunmi | F4: LH | G4: Tjs | H4: Inicio | I4: Final | J4: Días | K4: % Avance | L4: Estado | M4: Est. Interior
A5: 2.1.29 | B5: 22 | C5: Conhelo | D5: 1 | E5: =(F5+G5) -> 2 | F5: 1 | G5: 1 | I5: =IF(AND(H5<>"",J5<>""),H5+J5,"") | J5: 1 | K5: 0 | L5: =IF(K5=1,"Completado",IF(K5=0.9,"Falta LH",IF(K5=0,"Pendiente","En Proceso"))) -> Pendiente | M5: =IF(K5=1,"Operativa",IF(K5=0,"Pendiente","En Proceso")) -> Pendiente
A6: 2.1.30 | B6: 17 | C6: Toay | E6: =(F6+G6) -> 3 | F6: 1 | G6: 2 | H6: 46258 | I6: =IF(AND(H6<>"",J6<>""),H6+J6,"") -> 46259 | J6: 1 | K6: 0.3 | L6: =IF(K6=1,"Completado",IF(K6=0.9,"Falta LH",IF(K6=0,"Pendiente","En Proceso"))) -> En Proceso | M6: =IF(K6=1,"Operativa",IF(K6=0,"Pendiente","En Proceso")) -> En Proceso
A7: 2.1.31 | B7: 52 | C7: Toay | D7: 2 | E7: =(F7+G7) -> 5 | F7: 1 | G7: 4 | I7: =IF(AND(H7<>"",J7<>""),H7+J7,"") | J7: 1 | K7: 0 | L7: =IF(K7=1,"Completado",IF(K7=0.9,"Falta LH",IF(K7=0,"Pendiente","En Proceso"))) -> Pendiente | M7: =IF(K7=1,"Operativa",IF(K7=0,"Pendiente","En Proceso")) -> Pendiente
A8: 2.1.32 | B8: 117 | C8: Toay | E8: =(F8+G8) -> 3 | F8: 1 | G8: 2 | I8: =IF(AND(H8<>"",J8<>""),H8+J8,"") | J8: 1 | K8: 0.9 | L8: =IF(K8=1,"Completado",IF(K8=0.9,"Falta LH",IF(K8=0,"Pendiente","En Proceso"))) -> Falta LH | M8: =IF(K8=1,"Operativa",IF(K8=0,"Pendiente","En Proceso")) -> En Proceso
A9: 2.1.33 | B9: 49 | C9: Eduardo Castex | E9: =(F9+G9) -> 5 | F9: 1 | G9: 4 | I9: =IF(AND(H9<>"",J9<>""),H9+J9,"") | J9: 1 | K9: 0 | L9: =IF(K9=1,"Completado",IF(K9=0.9,"Falta LH",IF(K9=0,"Pendiente","En Proceso"))) -> Pendiente | M9: =IF(K9=1,"Operativa",IF(K9=0,"Pendiente","En Proceso")) -> Pendiente
A10: 2.1.34 | B10: 50 | C10: Eduardo Castex | D10: 2 | E10: =(F10+G10) -> 10 | F10: 1 | G10: 9 | I10: =IF(AND(H10<>"",J10<>""),H10+J10,"") | J10: 1 | K10: 0 | L10: =IF(K10=1,"Completado",IF(K10=0.9,"Falta LH",IF(K10=0,"Pendiente","En Proceso"))) -> Pendiente | M10: =IF(K10=1,"Operativa",IF(K10=0,"Pendiente","En Proceso")) -> Pendiente
A11: 2.1.35 | B11: 60 | C11: Eduardo Castex | E11: =(F11+G11) -> 1 | F11: 1 | G11: 0 | I11: =IF(AND(H11<>"",J11<>""),H11+J11,"") | J11: 1 | K11: 0 | L11: =IF(K11=1,"Completado",IF(K11=0.9,"Falta LH",IF(K11=0,"Pendiente","En Proceso"))) -> Pendiente | M11: =IF(K11=1,"Operativa",IF(K11=0,"Pendiente","En Proceso")) -> Pendiente
A12: 2.1.36 | B12: 132 | C12: Eduardo Castex | E12: =(F12+G12) -> 4 | F12: 1 | G12: 3 | I12: =IF(AND(H12<>"",J12<>""),H12+J12,"") | J12: 1 | K12: 0 | L12: =IF(K12=1,"Completado",IF(K12=0.9,"Falta LH",IF(K12=0,"Pendiente","En Proceso"))) -> Pendiente | M12: =IF(K12=1,"Operativa",IF(K12=0,"Pendiente","En Proceso")) -> Pendiente
A13: 2.1.37 | B13: 68 | C13: Anguil | D13: 1 | E13: =(F13+G13) -> 3 | F13: 1 | G13: 2 | H13: 46253 | I13: =IF(AND(H13<>"",J13<>""),H13+J13,"") -> 46254 | J13: 1 | K13: 0.9 | L13: =IF(K13=1,"Completado",IF(K13=0.9,"Falta LH",IF(K13=0,"Pendiente","En Proceso"))) -> Falta LH | M13: =IF(K13=1,"Operativa",IF(K13=0,"Pendiente","En Proceso")) -> En Proceso
A14: 2.1.38 | B14: 111 | C14: Uriburu | D14: 1 | E14: =(F14+G14) -> 2 | F14: 1 | G14: 1 | H14: 46258 | I14: =IF(AND(H14<>"",J14<>""),H14+J14,"") -> 46259 | J14: 1 | K14: 1 | L14: =IF(K14=1,"Completado",IF(K14=0.9,"Falta LH",IF(K14=0,"Pendiente","En Proceso"))) -> Completado | M14: =IF(K14=1,"Operativa",IF(K14=0,"Pendiente","En Proceso")) -> Operativa
A15: 2.1.39 | B15: 54 | C15: Realico | E15: =(F15+G15) -> 3 | F15: 1 | G15: 2 | I15: =IF(AND(H15<>"",J15<>""),H15+J15,"") | J15: 1 | K15: 0 | L15: =IF(K15=1,"Completado",IF(K15=0.9,"Falta LH",IF(K15=0,"Pendiente","En Proceso"))) -> Pendiente | M15: =IF(K15=1,"Operativa",IF(K15=0,"Pendiente","En Proceso")) -> Pendiente
A16: 2.1.40 | B16: 55 | C16: Realico | D16: 3 | E16: =(F16+G16) -> 10 | F16: 1 | G16: 9 | I16: =IF(AND(H16<>"",J16<>""),H16+J16,"") | J16: 1 | K16: 0 | L16: =IF(K16=1,"Completado",IF(K16=0.9,"Falta LH",IF(K16=0,"Pendiente","En Proceso"))) -> Pendiente | M16: =IF(K16=1,"Operativa",IF(K16=0,"Pendiente","En Proceso")) -> Pendiente
A17: 2.1.41 | B17: 56 | C17: Realico | E17: =(F17+G17) -> 4 | F17: 1 | G17: 3 | I17: =IF(AND(H17<>"",J17<>""),H17+J17,"") | J17: 1 | K17: 0 | L17: =IF(K17=1,"Completado",IF(K17=0.9,"Falta LH",IF(K17=0,"Pendiente","En Proceso"))) -> Pendiente | M17: =IF(K17=1,"Operativa",IF(K17=0,"Pendiente","En Proceso")) -> Pendiente
A18: 2.1.42 | B18: 78 | C18: Lonquimay | E18: =(F18+G18) -> 2 | F18: 1 | G18: 1 | H18: 46258 | I18: =IF(AND(H18<>"",J18<>""),H18+J18,"") -> 46259 | J18: 1 | K18: 1 | L18: =IF(K18=1,"Completado",IF(K18=0.9,"Falta LH",IF(K18=0,"Pendiente","En Proceso"))) -> Completado | M18: =IF(K18=1,"Operativa",IF(K18=0,"Pendiente","En Proceso")) -> Operativa
A19: 2.1.43 | B19: 138 | C19: Lonquimay | E19: 2 | G19: 2 | H19: 46258 | I19: 46259 | J19: 1 | K19: 1 | L19: =IF(K19=1,"Completado",IF(K19=0.9,"Falta LH",IF(K19=0,"Pendiente","En Proceso"))) -> Completado | M19: =IF(K19=1,"Operativa",IF(K19=0,"Pendiente","En Proceso")) -> Operativa
A20: 2.1.44 | B20: 46 | C20: General Acha | E20: =(F20+G20) -> 12 | F20: 1 | G20: 11 | I20: =IF(AND(H20<>"",J20<>""),H20+J20,"") | J20: 1 | K20: ,, | L20: =IF(K20=1,"Completado",IF(K20=0.9,"Falta LH",IF(K20=0,"Pendiente","En Proceso"))) -> En Proceso | M20: =IF(K20=1,"Operativa",IF(K20=0,"Pendiente","En Proceso")) -> En Proceso
A21: 2.1.45 | B21: 47 | C21: General Acha | D21: 5 | E21: =(F21+G21) -> 14 | F21: 1 | G21: 13 | I21: =IF(AND(H21<>"",J21<>""),H21+J21,"") | J21: 1 | K21: 0 | L21: =IF(K21=1,"Completado",IF(K21=0.9,"Falta LH",IF(K21=0,"Pendiente","En Proceso"))) -> Pendiente | M21: =IF(K21=1,"Operativa",IF(K21=0,"Pendiente","En Proceso")) -> Pendiente
A22: 2.1.46 | B22: 48 | C22: General Acha | E22: =(F22+G22) -> 17 | F22: 1 | G22: 16 | I22: =IF(AND(H22<>"",J22<>""),H22+J22,"") | J22: 1 | K22: 0 | L22: =IF(K22=1,"Completado",IF(K22=0.9,"Falta LH",IF(K22=0,"Pendiente","En Proceso"))) -> Pendiente | M22: =IF(K22=1,"Operativa",IF(K22=0,"Pendiente","En Proceso")) -> Pendiente
A23: 2.1.47 | B23: 130 | C23: General Acha | E23: =(F23+G23) -> 5 | F23: 1 | G23: 4 | I23: =IF(AND(H23<>"",J23<>""),H23+J23,"") | J23: 1 | K23: 0 | L23: =IF(K23=1,"Completado",IF(K23=0.9,"Falta LH",IF(K23=0,"Pendiente","En Proceso"))) -> Pendiente | M23: =IF(K23=1,"Operativa",IF(K23=0,"Pendiente","En Proceso")) -> Pendiente
A24: 2.1.48 | B24: 69 | C24: Quemu Quemu | E24: =(F24+G24) -> 8 | F24: 1 | G24: 7 | I24: =IF(AND(H24<>"",J24<>""),H24+J24,"") | J24: 1 | K24: 0 | L24: =IF(K24=1,"Completado",IF(K24=0.9,"Falta LH",IF(K24=0,"Pendiente","En Proceso"))) -> Pendiente | M24: =IF(K24=1,"Operativa",IF(K24=0,"Pendiente","En Proceso")) -> Pendiente
A25: 2.1.49 | B25: 58 | C25: Intendente Alvear | E25: =(F25+G25) -> 12 | F25: 1 | G25: 11 | I25: =IF(AND(H25<>"",J25<>""),H25+J25,"") | J25: 1 | K25: 0 | L25: =IF(K25=1,"Completado",IF(K25=0.9,"Falta LH",IF(K25=0,"Pendiente","En Proceso"))) -> Pendiente | M25: =IF(K25=1,"Operativa",IF(K25=0,"Pendiente","En Proceso")) -> Pendiente
A26: 2.1.50 | B26: 106 | C26: Intendente Alvear | D26: 2 | E26: =(F26+G26) -> 5 | F26: 1 | G26: 4 | I26: =IF(AND(H26<>"",J26<>""),H26+J26,"") | J26: 1 | K26: 0 | L26: =IF(K26=1,"Completado",IF(K26=0.9,"Falta LH",IF(K26=0,"Pendiente","En Proceso"))) -> Pendiente | M26: =IF(K26=1,"Operativa",IF(K26=0,"Pendiente","En Proceso")) -> Pendiente
A27: 2.1.51 | B27: 121 | C27: Intendente Alvear | E27: =(F27+G27) -> 5 | F27: 1 | G27: 4 | I27: =IF(AND(H27<>"",J27<>""),H27+J27,"") | J27: 1 | K27: 0 | L27: =IF(K27=1,"Completado",IF(K27=0.9,"Falta LH",IF(K27=0,"Pendiente","En Proceso"))) -> Pendiente | M27: =IF(K27=1,"Operativa",IF(K27=0,"Pendiente","En Proceso")) -> Pendiente
A28: 2.1.52 | B28: 66 | C28: Doblas | E28: =(F28+G28) -> 4 | F28: 1 | G28: 3 | H28: 46263 | I28: =IF(AND(H28<>"",J28<>""),H28+J28,"") -> 46264 | J28: 1 | K28: 0.9 | L28: =IF(K28=1,"Completado",IF(K28=0.9,"Falta LH",IF(K28=0,"Pendiente","En Proceso"))) -> Falta LH | M28: =IF(K28=1,"Operativa",IF(K28=0,"Pendiente","En Proceso")) -> En Proceso
A29: 2.1.53 | B29: 80 | C29: La Maruja | E29: =(F29+G29) -> 1 | F29: 1 | G29: 0 | I29: =IF(AND(H29<>"",J29<>""),H29+J29,"") | J29: 1 | K29: 0 | L29: =IF(K29=1,"Completado",IF(K29=0.9,"Falta LH",IF(K29=0,"Pendiente","En Proceso"))) -> Pendiente | M29: =IF(K29=1,"Operativa",IF(K29=0,"Pendiente","En Proceso")) -> Pendiente
A30: 2.1.54 | B30: 63 | C30: Alpachiri | E30: =(F30+G30) -> 2 | F30: 1 | G30: 1 | H30: 46262 | I30: =IF(AND(H30<>"",J30<>""),H30+J30,"") -> 46263 | J30: 1 | K30: 0.9 | L30: =IF(K30=1,"Completado",IF(K30=0.9,"Falta LH",IF(K30=0,"Pendiente","En Proceso"))) -> Falta LH | M30: =IF(K30=1,"Operativa",IF(K30=0,"Pendiente","En Proceso")) -> En Proceso
A31: 2.1.55 | B31: 64 | C31: Alpachiri | E31: =(F31+G31) -> 1 | F31: 1 | G31: 0 | I31: =IF(AND(H31<>"",J31<>""),H31+J31,"") | J31: 1 | K31: 0 | L31: =IF(K31=1,"Completado",IF(K31=0.9,"Falta LH",IF(K31=0,"Pendiente","En Proceso"))) -> Pendiente | M31: =IF(K31=1,"Operativa",IF(K31=0,"Pendiente","En Proceso")) -> Pendiente
A32: 2.1.56 | B32: 73 | C32: Bernasconi | D32: 1 | E32: =(F32+G32) -> 1 | F32: 1 | G32: 0 | H32: 46260 | I32: =IF(AND(H32<>"",J32<>""),H32+J32,"") -> 46261 | J32: 1 | K32: 0.9 | L32: =IF(K32=1,"Completado",IF(K32=0.9,"Falta LH",IF(K32=0,"Pendiente","En Proceso"))) -> Falta LH | M32: =IF(K32=1,"Operativa",IF(K32=0,"Pendiente","En Proceso")) -> En Proceso
A33: 2.1.57 | B33: 74 | C33: Bernasconi | E33: =(F33+G33) -> 2 | F33: 1 | G33: 1 | H33: 46260 | I33: =IF(AND(H33<>"",J33<>""),H33+J33,"") -> 46261 | J33: 1 | K33: 1 | L33: =IF(K33=1,"Completado",IF(K33=0.9,"Falta LH",IF(K33=0,"Pendiente","En Proceso"))) -> Completado | M33: =IF(K33=1,"Operativa",IF(K33=0,"Pendiente","En Proceso")) -> Operativa
A34: 2.1.58 | B34: 75 | C34: Jacinto Arauz | D34: 1 | E34: =(F34+G34) -> 5 | F34: 1 | G34: 4 | H34: 46260 | I34: =IF(AND(H34<>"",J34<>""),H34+J34,"") -> 46261 | J34: 1 | K34: 0.9 | L34: =IF(K34=1,"Completado",IF(K34=0.9,"Falta LH",IF(K34=0,"Pendiente","En Proceso"))) -> Falta LH | M34: =IF(K34=1,"Operativa",IF(K34=0,"Pendiente","En Proceso")) -> En Proceso
A35: 2.1.59 | B35: 81 | C35: Colonia Baron | E35: =(F35+G35) -> 4 | F35: 1 | G35: 3 | H35: 46258 | I35: =IF(AND(H35<>"",J35<>""),H35+J35,"") -> 46259 | J35: 1 | K35: 0.9 | L35: =IF(K35=1,"Completado",IF(K35=0.9,"Falta LH",IF(K35=0,"Pendiente","En Proceso"))) -> Falta LH | M35: =IF(K35=1,"Operativa",IF(K35=0,"Pendiente","En Proceso")) -> En Proceso
A36: 2.1.60 | B36: 82 | C36: Colonia Baron | E36: =(F36+G36) -> 4 | F36: 1 | G36: 3 | H36: 46258 | I36: =IF(AND(H36<>"",J36<>""),H36+J36,"") -> 46259 | J36: 1 | K36: 1 | L36: =IF(K36=1,"Completado",IF(K36=0.9,"Falta LH",IF(K36=0,"Pendiente","En Proceso"))) -> Completado | M36: =IF(K36=1,"Operativa",IF(K36=0,"Pendiente","En Proceso")) -> Operativa
A37: 2.1.61 | B37: 87 | C37: Guatrache | D37: 2 | E37: =(F37+G37) -> 8 | F37: 1 | G37: 7 | H37: 46262 | I37: =IF(AND(H37<>"",J37<>""),H37+J37,"") -> 46263 | J37: 1 | K37: 0.9 | L37: =IF(K37=1,"Completado",IF(K37=0.9,"Falta LH",IF(K37=0,"Pendiente","En Proceso"))) -> Falta LH | M37: =IF(K37=1,"Operativa",IF(K37=0,"Pendiente","En Proceso")) -> En Proceso
A38: 2.1.62 | B38: 88 | C38: Guatrache | E38: =(F38+G38) -> 3 | F38: 1 | G38: 2 | H38: 46262 | I38: =IF(AND(H38<>"",J38<>""),H38+J38,"") -> 46263 | J38: 1 | K38: 0.9 | L38: =IF(K38=1,"Completado",IF(K38=0.9,"Falta LH",IF(K38=0,"Pendiente","En Proceso"))) -> Falta LH | M38: =IF(K38=1,"Operativa",IF(K38=0,"Pendiente","En Proceso")) -> En Proceso
A39: 2.1.63 | B39: 84 | C39: Ingeniero Luiggi | E39: =(F39+G39) -> 4 | F39: 1 | G39: 3 | I39: =IF(AND(H39<>"",J39<>""),H39+J39,"") | J39: 1 | K39: 0 | L39: =IF(K39=1,"Completado",IF(K39=0.9,"Falta LH",IF(K39=0,"Pendiente","En Proceso"))) -> Pendiente | M39: =IF(K39=1,"Operativa",IF(K39=0,"Pendiente","En Proceso")) -> Pendiente
A40: 2.1.64 | B40: 85 | C40: Ingeniero Luiggi | E40: =(F40+G40) -> 6 | F40: 1 | G40: 5 | I40: =IF(AND(H40<>"",J40<>""),H40+J40,"") | J40: 1 | K40: 0 | L40: =IF(K40=1,"Completado",IF(K40=0.9,"Falta LH",IF(K40=0,"Pendiente","En Proceso"))) -> Pendiente | M40: =IF(K40=1,"Operativa",IF(K40=0,"Pendiente","En Proceso")) -> Pendiente
...
